<?xml version="1.0"?>
<robot>
  <xmlns:xacro="http://www.ros.org/wiki/xacro" name="kbot">
 
  <xacro:property name="base_width" value="0.16"/>
  <xacro:property name="base_len" value="0.16"/>
  <xacro:property name="wheel_radius" value="0.035"/>
  <xacro:property name="base_wheel_gap" value="0.007"/>
  <xacro:property name="wheel_separation" value="0.15"/>
  <xacro:property name="wheel_joint_offset" value="0.02"/>

<link name="base_link">
    <inertial>
      <mass value="5"/>
      <origin xyz="0 0 0.52" rpy="0 0 3.14"/>
      <inertia ixx="1.392949" ixy="0" ixz="-0.000108" iyy="1.392846" iyz="-0.000000" izz="-1.000000"/>
    </inertial>
	<visual>
	<origin xyz="0 0 0.52" rpy="0 0 3.14"/>
	<geometry>
        <mesh filename="package://per_robot_urdf/meshes/two_plate.dae"/>
      </geometry>
      <material name="red"/>
    </visual>
    <collision >
	<origin xyz="0 0 0.52" rpy="0 0 3.14"/>
      <geometry>
        <mesh filename="package://per_robot_urdf/meshes/two_plate.dae"/>
      </geometry>
    </collision>

  </link>


<xacro:macro name="cylinder_inertia" params="m r h">
    <inertial>
      <mass value="${m}"/>
      <inertia ixx="${m*(3*r*r+h*h)/12}" ixy = "0" ixz = "0" iyy="${m*(3*r*r+h*h)/12}" iyz = "0" izz="${m*r*r/2}"/> 
    </inertial>
  </xacro:macro>

  <xacro:macro name="wheel" params="prefix reflect">
    <link name="${prefix}_wheel">
      <visual>
        <origin xyz="0 0 0" rpy="${pi/2} 0 0"/>
        <geometry>
          <cylinder radius="${wheel_radius}" length="0.005"/>
        </geometry>
      </visual>
      <collision>
        <origin xyz="0 0 0" rpy="${pi/2} 0 0"/>
        <geometry>
          <cylinder radius="${wheel_radius}" length="0.005"/>
        </geometry>
      </collision>
      <xacro:cylinder_inertia m="10" r="${wheel_radius}" h="0.005"/>
    </link>

    <joint name="${prefix}_wheel_joint" type="continuous">
      <axis xyz="0 1 0" rpy="0 0 0" />
      <parent link="base_link"/>
      <child link="${prefix}_wheel"/>
      <origin xyz="${wheel_joint_offset} ${((base_width/2)+base_wheel_gap)*reflect} -0.005" rpy="0 0 0"/>
    </joint>
  </xacro:macro>

  <xacro:wheel prefix="left" reflect="1"/>
  <xacro:wheel prefix="right" reflect="-1"/>



</robot>
