<?xml version="1.0"?>
<robot name="m2wr" xmlns:xacro="http://www.ros.org/wiki/xacro">
  <material name="black">
    <color rgba="0.0 0.0 0.0 1.0"/>
  </material>
  <material name="blue">
    <color rgba="0.203125 0.23828125 0.28515625 1.0"/>
  </material>
  <material name="green">
    <color rgba="0.0 0.8 0.0 1.0"/>
  </material>
  <material name="grey">
    <color rgba="0.2 0.2 0.2 1.0"/>
  </material>
  <material name="orange">
    <color rgba="1.0 0.423529411765 0.0392156862745 1.0"/>
  </material>
  <material name="brown">
    <color rgba="0.870588235294 0.811764705882 0.764705882353 1.0"/>
  </material>
  <material name="red">
    <color rgba="0.80078125 0.12890625 0.1328125 1.0"/>
  </material>
  <material name="white">
    <color rgba="1.0 1.0 1.0 1.0"/>
  </material>
  
    <gazebo reference="link_chassis">
    <material>Gazebo/Orange</material>
  </gazebo>
  <gazebo reference="link_left_wheel">
    <material>Gazebo/Green</material>
  </gazebo>
  <gazebo reference="link_right_wheel">
    <material>Gazebo/Green</material>
  </gazebo>
  <gazebo reference="link_left2_wheel">
    <material>Gazebo/Green</material>
  </gazebo>
  
  <gazebo>
    <plugin filename="libgazebo_ros_diff_drive.so" name="differential_drive_controller">
      <alwaysOn>true</alwaysOn>
      <updateRate>20</updateRate>
      <leftJoint>joint_left_wheel</leftJoint>
      <rightJoint>joint_right_wheel</rightJoint>
      <wheelSeparation>0.4</wheelSeparation>
      <wheelDiameter>0.2</wheelDiameter>
      <torque>0.1</torque>
      <commandTopic>cmd_vel</commandTopic>
      <odometryTopic>odom</odometryTopic>
      <odometryFrame>odom</odometryFrame>
      <robotBaseFrame>link_chassis</robotBaseFrame>
    </plugin>
  </gazebo>
  
  <gazebo reference="sensor_laser">
    <sensor type="ray" name="head_hokuyo_sensor">
      <pose>0 0 0 0 0 0</pose>
      <visualize>false</visualize>
      <update_rate>20</update_rate>
      <ray>
        <scan>
          <horizontal>
            <samples>720</samples>
            <resolution>1</resolution>
            <min_angle>-1.570796</min_angle>
            <max_angle>1.570796</max_angle>
          </horizontal>
        </scan>
        <range>
          <min>0.10</min>
          <max>10.0</max>
          <resolution>0.01</resolution>
        </range>
        <noise>
          <type>gaussian</type>
          <mean>0.0</mean>
          <stddev>0.01</stddev>
        </noise>
      </ray>
      <plugin name="gazebo_ros_head_hokuyo_controller" filename="libgazebo_ros_laser.so">
        <topicName>/m2wr/laser/scan</topicName>
        <frameName>sensor_laser</frameName>
      </plugin>
    </sensor>
  </gazebo>
  

<link name="base_link">
    <inertial>
      <mass value="5"/>
      <origin xyz="0 0 0.52" rpy="0 0 3.14"/>
      <inertia ixx="1.392949" ixy="0" ixz="-0.000108" iyy="1.392846" iyz="-0.000000" izz="-1.000000"/>
    </inertial>
	<visual>
	<origin xyz="0 0 0.52" rpy="0 0 3.14"/>
	<geometry>
        <mesh filename="package://per_robot_urdf/meshes/two_plate.dae"/>
      </geometry>
      <material name="red"/>
    </visual>
    <collision >
	<origin xyz="0 0 0.52" rpy="0 0 3.14"/>
      <geometry>
        <mesh filename="package://per_robot_urdf/meshes/two_plate.dae"/>
      </geometry>
    </collision>

  </link>

  

    <link name="link_right_wheel">
    <inertial>
      <mass value="0.2"/>
      <origin rpy="0 1.570700 0" xyz="2.195 0 0.27"/>
      <inertia ixx="0.003726" ixy="0" ixz="0" iyy="0.003726" iyz="0" izz="0.003645"/>
    </inertial>
    <collision name="link_right_wheel_collision">
	<origin rpy="0 1.570700 0" xyz="2.195 0 0.27"/>
	<geometry>
	 <cylinder length=".07" radius=".27" />
	</geometry>
    </collision>
    <visual name="link_right_wheel_visual">
	<origin rpy="0 1.570700 0" xyz="2.195 0 0.27"/>
	<geometry>
	 <cylinder length="0.07" radius="0.27" />
	</geometry>
    </visual>
  </link>


  <joint name="joint_right_wheel" type="continuous">
    <child link="link_right_wheel"/>
    <parent link="base_link"/>
    <axis rpy="0 0 0" xyz="2.195 0 0.27"/>
  </joint>




    <link name="link_left_wheel">
    <inertial>
      <mass value="0.2"/>
      <origin rpy="0 1.570700 1.0472" xyz="-1.10000 -1.9 0.27"/>
      <inertia ixx="0.003726" ixy="0" ixz="0" iyy="0.003726" iyz="0" izz="0.003645"/>
    </inertial>
    <collision name="link_left_wheel_collision">
	<origin rpy="0 1.570700 1.0472" xyz="-1.10000 -1.9 0.27"/>
	<geometry>
	 <cylinder length=".07" radius=".27" />
	</geometry>
    </collision>
    <visual name="link_left_wheel_visual">
	<origin rpy="0 1.570700 1.0472" xyz="-1.10000 -1.9 0.27"/>
	<geometry>
	 <cylinder length="0.07" radius="0.27" />
	</geometry>
    </visual>
  </link>


  <joint name="joint_left_wheel" type="continuous">
    <child link="link_left_wheel"/>
    <parent link="base_link"/>
    <axis rpy="0 0 0" xyz="-1.10000 -1.9 0.27"/>
  </joint>



    <link name="link_left2_wheel">
    <inertial>
      <mass value="0.2"/>
      <origin rpy="0 1.570700 2.0944" xyz="-1.10000 1.9 0.27"/>
      <inertia ixx="0.003726" ixy="0" ixz="0" iyy="0.003726" iyz="0" izz="0.003645"/>
    </inertial>
    <collision name="link_left2_wheel_collision">
	<origin rpy="0 1.570700 2.0944" xyz="-1.10000 1.9 0.27"/>
	<geometry>
	 <cylinder length=".07" radius=".27" />
	</geometry>
    </collision>
    <visual name="link_left2_wheel_visual">
	<origin rpy="0 1.570700 2.0944" xyz="-1.10000 1.9 0.27"/>
	<geometry>
	 <cylinder length="0.07" radius="0.27" />
	</geometry>
    </visual>
  </link>


  <joint name="joint_left2_wheel" type="continuous">
    <child link="link_left2_wheel"/>
    <parent link="base_link"/>
    <axis rpy="0 0 0" xyz="-1.10000 1.9 0.27"/>
  </joint>


<!--
    <link name="link_left_wheel">
	<pose>1.10000 -1.9 -0.3 0 1.570700 2.0944</pose>
    <inertial>
      <mass value="0.2"/>
      <origin rpy="0 1.570700 2.0944"/>
      <inertia ixx="0.000526666666667" ixy="0" ixz="0" iyy="0.000526666666667" iyz="0" izz="0.001"/>
    </inertial>
    <collision name="link_left_wheel_collision">
	<origin rpy="0 1.570700 2.0944"/>
	<geometry>
	 <cylinder length=".07" radius=".27" />
	</geometry>
    </collision>
    <visual name="link_left_wheel_visual">
	<origin rpy="0 1.570700 2.0944"/>
	<geometry>
	 <cylinder length="0.07" radius="0.27" />
	</geometry>
    </visual>
  </link>
-->


<!--
    <link name="link_left2_wheel">
	<pose>-2.195 0 -0.3 0 1.570700 0</pose>
    <inertial>
      <mass value="0.2"/>
      <origin rpy="0 1.570700 0"/>
      <inertia ixx="0.000526666666667" ixy="0" ixz="0" iyy="0.000526666666667" iyz="0" izz="0.001"/>
    </inertial>
    <collision name="link_left2_wheel_collision">
	<origin rpy="0 1.570700 0"/>
	<geometry>
	 <cylinder length=".07" radius=".27" />
	</geometry>
    </collision>
    <visual name="link_left2_wheel_visual">
	<origin rpy="0 1.570700 0"/>
	<geometry>
	 <cylinder length="0.07" radius="0.27" />
	</geometry>
    </visual>
  </link>

-->

  
  
</robot>

