<?xml version="1.0" ?>
<!-- =================================================================================== -->
<!-- |    This document was autogenerated by xacro from backup_my_model.xacro          | -->
<!-- |    EDITING THIS FILE BY HAND IS NOT RECOMMENDED                                 | -->
<!-- =================================================================================== -->
<robot name="robot">
  <material name="black">
    <color rgba="0.0 0.0 0.0 1.0"/>
  </material>
  <material name="blue">
    <color rgba="0.203125 0.23828125 0.28515625 1.0"/>
  </material>
  <material name="green">
    <color rgba="0.0 0.8 0.0 1.0"/>
  </material>
  <material name="grey">
    <color rgba="0.2 0.2 0.2 1.0"/>
  </material>
  <material name="orange">
    <color rgba="1.0 0.423529411765 0.0392156862745 1.0"/>
  </material>
  <material name="brown">
    <color rgba="0.870588235294 0.811764705882 0.764705882353 1.0"/>
  </material>
  <material name="red">
    <color rgba="0.80078125 0.12890625 0.1328125 1.0"/>
  </material>
  <material name="white">
    <color rgba="1.0 1.0 1.0 1.0"/>
  </material>
  <gazebo reference="link_chassis">
    <material>Gazebo/Orange</material>
  </gazebo>
  <gazebo reference="link_left_wheel">
    <material>Gazebo/Orange</material>
  </gazebo>
  <gazebo reference="link_right_wheel">
    <material>Gazebo/Orange</material>
  </gazebo>
  <gazebo reference="link_left2_wheel">
    <material>Gazebo/Orange</material>
  </gazebo>
  <gazebo reference="camera_link">
    <material>Gazebo/Blue</material>
  </gazebo>
  <gazebo reference="sonar_link">
    <material>Gazebo/Black</material>
  </gazebo>
  <gazebo>
    <plugin filename="libgazebo_ros_control.so" name="gazebo_ros_control">
      <robotNamespace>/robot</robotNamespace>
    </plugin>
  </gazebo>
  <gazebo>
    <plugin filename="libgazebo_ros_diff_drive.so" name="differential_drive_controller">
      <alwaysOn>true</alwaysOn>
      <updateRate>20</updateRate>
      <leftJoint>joint_left_wheel</leftJoint>
      <rightJoint>joint_right_wheel</rightJoint>
      <wheelSeparation>0.4</wheelSeparation>
      <wheelDiameter>0.2</wheelDiameter>
      <torque>0.1</torque>
      <commandTopic>cmd_vel</commandTopic>
      <odometryTopic>odom</odometryTopic>
      <odometryFrame>odom</odometryFrame>
      <robotBaseFrame>link_chassis</robotBaseFrame>
    </plugin>
  </gazebo>
  <gazebo reference="sensor_laser">
    <sensor name="head_hokuyo_sensor" type="ray">
      <pose>0 0 0 0 0 0</pose>
      <visualize>false</visualize>
      <update_rate>20</update_rate>
      <ray>
        <scan>
          <horizontal>
            <samples>720</samples>
            <resolution>1</resolution>
            <min_angle>-1.570796</min_angle>
            <max_angle>1.570796</max_angle>
          </horizontal>
        </scan>
        <range>
          <min>0.10</min>
          <max>10.0</max>
          <resolution>0.01</resolution>
        </range>
        <noise>
          <type>gaussian</type>
          <mean>0.0</mean>
          <stddev>0.01</stddev>
        </noise>
      </ray>
      <plugin filename="libgazebo_ros_laser.so" name="gazebo_ros_head_hokuyo_controller">
        <topicName>/m2wr/laser/scan</topicName>
        <frameName>sensor_laser</frameName>
      </plugin>
    </sensor>
  </gazebo>
  <link name="base_link">
    <inertial>
      <mass value="20"/>
      <origin rpy="0 0 3.14" xyz="0 0 0.52"/>
      <inertia ixx="1.392949" ixy="0" ixz="-0.000108" iyy="1.392846" iyz="-0.000000" izz="-1.000000"/>
    </inertial>
    <visual>
      <origin rpy="0 0 3.14" xyz="0 0 0.52"/>
      <geometry>
        <mesh filename="package://rob_pkg/meshes/two_plate.dae "/>
      </geometry>
      <material name="red"/>
    </visual>
    <collision>
      <origin rpy="0 0 3.14" xyz="0 0 0.52"/>
      <geometry>
        <mesh filename="package://rob_pkg/meshes/two_plate.dae"/>
      </geometry>
    </collision>
  </link>
  <link name="camera_link">
    <collision>
      <origin rpy="0 0 0" xyz="0 0 0.43"/>
      <geometry>
        <box size=".1 .1 .1"/>
      </geometry>
    </collision>
    <visual>
      <origin rpy="0 0 0" xyz="0 0 0.43"/>
      <geometry>
        <box size=".1 .1 .1"/>
      </geometry>
      <material name="grey">
        <color rgba="0.2 0.2 0.2 1.0"/>
      </material>
    </visual>
    <inertial>
      <mass value="0.001"/>
      <inertia ixx="1.6666666666666669e-06" ixy="0.0" ixz="0.0" iyy="1.6666666666666669e-06" iyz="0.0" izz="1.6666666666666669e-06"/>
    </inertial>
  </link>
  <joint name="camera_joint" type="fixed">
    <parent link="base_link"/>
    <child link="camera_link"/>
    <origin rpy="0 0 0" xyz="2.195 0 0.5"/>
    <axis xyz="1 0 0"/>
  </joint>
  <gazebo reference="camera_link">
    <sensor name="camera_camera_sensor" type="camera">
      <update_rate>30.0</update_rate>
      <camera>
        <pose>0.035 0 0.078 0 0 0</pose>
        <horizontal_fov>1.4835298641951802</horizontal_fov>
        <image>
          <format>R8G8B8</format>
          <width>1020</width>
          <height>1020</height>
        </image>
        <clip>
          <near>0.01</near>
          <far>100</far>
        </clip>
      </camera>
      <plugin filename="libgazebo_ros_camera.so" name="camera_camera_controller">
        <alwaysOn>true</alwaysOn>
        <updateRate>0.0</updateRate>
        <cameraName>robot_sensor/camera</cameraName>
        <imageTopicName>image_raw</imageTopicName>
        <cameraInfoTopicName>camera_info</cameraInfoTopicName>
        <frameName>camera_link</frameName>
        <hackBaseline>0.07</hackBaseline>
        <distortionK1>0.0</distortionK1>
        <distortionK2>0.0</distortionK2>
        <distortionK3>0.0</distortionK3>
        <distortionT1>0.0</distortionT1>
        <distortionT2>0.0</distortionT2>
      </plugin>
    </sensor>
  </gazebo>
  <link name="sonar_link">
    <collision>
      <origin rpy="0 0 0" xyz="0 0 0.43"/>
      <geometry>
        <box size=".1 .1 .1"/>
      </geometry>
    </collision>
    <visual>
      <origin rpy="0 0 0" xyz="0 0 0.43"/>
      <geometry>
        <box size=".1 .1 .1"/>
      </geometry>
      <material name="grey">
        <color rgba="0.2 0.2 0.2 1.0"/>
      </material>
    </visual>
    <inertial>
      <mass value="0.001"/>
      <inertia ixx="1.6666666666666669e-06" ixy="0.0" ixz="0.0" iyy="1.6666666666666669e-06" iyz="0.0" izz="1.6666666666666669e-06"/>
    </inertial>
  </link>
  <joint name="sonar_joint" type="fixed">
    <parent link="base_link"/>
    <child link="sonar_link"/>
    <origin rpy="0 0 0" xyz="-1.10000 1.9 0.5"/>
    <axis xyz="1 0 0"/>
  </joint>
  <gazebo reference="sonar_link">
    <sensor name="sonar" type="ray">
      <pose>0.25 0 0 0 0 0</pose>
      <update_rate>5</update_rate>
      <ray>
        <scan>
          <horizontal>
            <samples>5</samples>
            <resolution>1.0</resolution>
            <min_angle>-0.25</min_angle>
            <max_angle>0.25</max_angle>
          </horizontal>
          <vertical>
            <samples>5</samples>
            <resolution>1</resolution>
            <min_angle>-0.25</min_angle>
            <max_angle>0.25</max_angle>
          </vertical>
        </scan>
        <range>
          <min>0.01</min>
          <max>0.75</max>
          <resolution>0.01</resolution>
        </range>
      </ray>
      <plugin filename="libgazebo_ros_range.so" name="gazebo_ros_range">
        <gaussianNoise>0.005</gaussianNoise>
        <alwaysOn>true</alwaysOn>
        <updateRate>5</updateRate>
        <topicName>sonar</topicName>
        <frameName>sonar_link</frameName>
        <fov>0.5</fov>
        <radiation>ultrasound</radiation>
      </plugin>
    </sensor>
  </gazebo>
  <link name="link_right_wheel">
    <mass value="1"/>
    <origin rpy="0 1.570700 0" xyz="2.195 0 0.27"/>
    <collision name="link_right_wheel_collision">
      <geometry>
        <cylinder length=".07" radius=".27"/>
      </geometry>
    </collision>
    <visual name="link_right_wheel_visual">
      <geometry>
        <cylinder length="0.07" radius="0.27"/>
      </geometry>
    </visual>
    <inertial>
      <mass value="1"/>
      <inertia ixx="0.018633333333333335" ixy="0" ixz="0" iyy="0.018633333333333335" iyz="0" izz="0.03645"/>
    </inertial>
  </link>
  <joint name="joint_right_wheel" type="continuous">
    <origin rpy="0 1.570700 0" xyz="2.195 0 0.27"/>
    <child link="link_right_wheel"/>
    <parent link="base_link"/>
    <axis rpy="0 0 0" xyz="0 0 1"/>
  </joint>
  <!-- Rear wheels transmission -->
  <transmission name="transmission_right_wheel">
    <type>transmission_interface/SimpleTransmission</type>
    <joint name="joint_right_wheel">
      <hardwareInterface>hardware_interface/EffortJointInterface</hardwareInterface>
    </joint>
    <actuator name="motor_right_wheel">
      <hardwareInterface>hardware_interface/EffortJointInterface</hardwareInterface>
      <mechanicalReduction>1</mechanicalReduction>
    </actuator>
  </transmission>
  <link name="link_left_wheel">
    <mass value="1"/>
    <origin rpy="0 1.570700 1.0472" xyz="-1.10000 -1.9 0.27"/>
    <collision name="link_left_wheel_collision">
      <geometry>
        <cylinder length=".07" radius=".27"/>
      </geometry>
    </collision>
    <visual name="link_left_wheel_visual">
      <geometry>
        <cylinder length="0.07" radius="0.27"/>
      </geometry>
    </visual>
    <inertial>
      <mass value="1"/>
      <inertia ixx="0.018633333333333335" ixy="0" ixz="0" iyy="0.018633333333333335" iyz="0" izz="0.03645"/>
    </inertial>
  </link>
  <joint name="joint_left_wheel" type="continuous">
    <origin rpy="0 1.570700 1.0472" xyz="-1.10000 -1.9 0.27"/>
    <child link="link_left_wheel"/>
    <parent link="base_link"/>
    <axis rpy="0 0 0" xyz="0 0 1"/>
  </joint>
  <!-- Rear wheels transmission -->
  <transmission name="transmission_left_wheel">
    <type>transmission_interface/SimpleTransmission</type>
    <joint name="joint_left_wheel">
      <hardwareInterface>hardware_interface/EffortJointInterface</hardwareInterface>
    </joint>
    <actuator name="motor_left_wheel">
      <hardwareInterface>hardware_interface/EffortJointInterface</hardwareInterface>
      <mechanicalReduction>1</mechanicalReduction>
    </actuator>
  </transmission>
  <link name="link_left2_wheel">
    <mass value="1"/>
    <origin rpy="0 1.570700 2.0944" xyz="-1.10000 1.9 0.27"/>
    <collision name="link_left2_wheel_collision">
      <geometry>
        <cylinder length=".07" radius=".27"/>
      </geometry>
    </collision>
    <visual name="link_left2_wheel_visual">
      <geometry>
        <cylinder length="0.07" radius="0.27"/>
      </geometry>
    </visual>
    <inertial>
      <mass value="1"/>
      <inertia ixx="0.018633333333333335" ixy="0" ixz="0" iyy="0.018633333333333335" iyz="0" izz="0.03645"/>
    </inertial>
  </link>
  <joint name="joint_left2_wheel" type="continuous">
    <origin rpy="0 1.570700 2.0944" xyz="-1.10000 1.9 0.27"/>
    <child link="link_left2_wheel"/>
    <parent link="base_link"/>
    <axis rpy="0 0 0" xyz="0 0 1"/>
  </joint>
  <!-- Rear wheels transmission -->
  <transmission name="transmission_left2_wheel">
    <type>transmission_interface/SimpleTransmission</type>
    <joint name="joint_left2_wheel">
      <hardwareInterface>hardware_interface/EffortJointInterface</hardwareInterface>
    </joint>
    <actuator name="motor_left2_wheel">
      <hardwareInterface>hardware_interface/EffortJointInterface</hardwareInterface>
      <mechanicalReduction>1</mechanicalReduction>
    </actuator>
  </transmission>
</robot>

