<?xml version="1.0"?>
<robot name="wheel_def" xmlns:xacro="http://ros.org/wiki/xacro">
     <xacro:macro name="cylinder_inertia" params="m r h">
    <inertial>
      <mass value="${m}"/>
      <inertia ixx="${m*(3*r*r+h*h)/12}" ixy = "0" ixz = "0" iyy="${m*(3*r*r+h*h)/12}" iyz = "0" izz="${m*r*r/2}"/> 
    </inertial>
  </xacro:macro> 

 
     <xacro:macro name="surface_gen" params="main_link_name">
      <gazebo reference="${main_link_name}">
      <mu1>1</mu1>
      <mu2>1</mu2>
      <fdir1>1 0 0</fdir1>
      <maxContacts>1</maxContacts>
      <minDepth>0.005</minDepth>
      <gravity>true</gravity>
      <surface>
        <friction>
          <torsional>
            <coefficient>10</coefficient>
            <use_patch_radius>false</use_patch_radius>
            <!-- should be the same as collision sphere radius -->
            <surface_radius>0.02175</surface_radius>
            <patch_radius>0.01</patch_radius>
          </torsional>
        </friction>
        <contact>
      <poissons_ratio>0.5</poissons_ratio>
        <elastic_modulus>1e8</elastic_modulus>
      </contact>
    </surface>
  </gazebo>
  </xacro:macro> 


  <xacro:macro name="complex_wheel_gen" params="wheel_name this_wheel_x this_wheel_y this_wheel_z this_wheel_pitch this_wheel_yaw this_wheel_roll">
    <link name="link_${wheel_name}_rim">
      <mass value="${rim_mass}"/>
      <origin rpy="${this_wheel_pitch} ${this_wheel_yaw} ${this_wheel_roll}" xyz="${this_wheel_x} ${this_wheel_y} ${this_wheel_z}"/>
      <collision name="link_${wheel_name}_rim_collision">
        <geometry>
         <mesh filename="package://rob_pkg/meshes/rim.stl" scale="${wheel_scale} ${wheel_scale} ${wheel_scale}" />
        </geometry>
      </collision>
     <visual name="link_${wheel_name}_rim_visual">
      <geometry>
       <mesh filename="package://rob_pkg/meshes/rim.stl" scale="${wheel_scale} ${wheel_scale} ${wheel_scale}" />
      </geometry>
     </visual>
         <inertial>
      <mass value="${rim_mass}"/>
      <inertia 
        ixx="${dummy_scale*(-1)}" ixy = "${dummy_scale*(0.000170)}" ixz = "${dummy_scale*(-0.000422)}" 
        iyx="${dummy_scale*(-0.000455)}" iyy = "${dummy_scale*(-0.397695)}" iyz = "${dummy_scale*(0.917517)}" 
        izx="${dummy_scale*(-0.000012)}" izy = "${dummy_scale*(0.917517)}" izz = "${dummy_scale*(0.397695)}" 
       /> 
    </inertial>

    </link>

    <link name="link_${wheel_name}_roller_1">
      <origin rpy="${0} ${0} 0" xyz="${-0.0055*roller_scale} ${0.01355*roller_scale} ${0*roller_scale}"/>
       <collision name="link_${wheel_name}_1_roller_collision">
        <geometry>
         <mesh filename="package://rob_pkg/meshes/roller.stl" scale="${roller_scale} ${roller_scale} ${roller_scale}"/>
        </geometry>
      </collision>
     <visual name="link_${wheel_name}_1_roller_visual">
      <geometry>
       <mesh filename="package://rob_pkg/meshes/roller.stl" scale="${roller_scale} ${roller_scale} ${roller_scale}"/>
      </geometry>
     </visual>
      <inertial>
      <mass value="${roller_mass}"/>
      <inertia ixx="${2.53776e-08}" ixy = "0" ixz = "0" iyy="${2.53776e-08}" iyz = "0" izz="${1.47666e-08}"/> 
    </inertial>
    </link>

<xacro:surface_gen main_link_name="link_${wheel_name}_roller_1"/>

  <joint name="joint_${wheel_name}_1" type="continuous">
  <origin rpy="${0} ${0} 0" xyz="${-0.0055*roller_scale} ${0.01355*roller_scale} ${0*roller_scale}"/>
    <child link="link_${wheel_name}_roller_1"/>
    <parent link="link_${wheel_name}_rim"/>
    <axis rpy="0 0 0" xyz="0 0 1"/>
  </joint>


   <link name="link_${wheel_name}_roller_2">
      <origin rpy="${0.875398} ${0} 0" xyz="${0.0055*roller_scale} ${0.009581*roller_scale} ${0.009581*roller_scale}"/>
       <collision name="link_${wheel_name}_2_roller_collision">
        <geometry>
         <mesh filename="package://rob_pkg/meshes/roller.stl" scale="${roller_scale} ${roller_scale} ${roller_scale}"/>
        </geometry>
      </collision>
     <visual name="link_${wheel_name}_2_roller_visual">
      <geometry>
       <mesh filename="package://rob_pkg/meshes/roller.stl" scale="${roller_scale} ${roller_scale} ${roller_scale}"/>
      </geometry>
     </visual>
      <inertial>
      <mass value="${roller_mass}"/>
      <inertia ixx="${2.53776e-08}" ixy = "0" ixz = "0" iyy="${2.53776e-08}" iyz = "0" izz="${1.47666e-08}"/> 
    </inertial>
    </link>

    <xacro:surface_gen main_link_name="link_${wheel_name}_roller_2"/>

  <joint name="joint_${wheel_name}_2" type="continuous">
  <origin rpy="${0.875398} ${0} 0" xyz="${0.0055*roller_scale} ${0.009581*roller_scale} ${0.009581*roller_scale}"/>
    <child link="link_${wheel_name}_roller_2"/>
    <parent link="link_${wheel_name}_rim"/>
    <axis rpy="0 0 0" xyz="0 0 1"/>
    
  </joint>

     <link name="link_${wheel_name}_roller_3">
      <origin rpy="${1.5708} ${0} 0" xyz="${-0.0055*roller_scale} ${0*roller_scale} ${0.01355*roller_scale}"/>
       <collision name="link_${wheel_name}_3_roller_collision">
        <geometry>
         <mesh filename="package://rob_pkg/meshes/roller.stl" scale="${roller_scale} ${roller_scale} ${roller_scale}"/>
        </geometry>
      </collision>
     <visual name="link_${wheel_name}_3_roller_visual">
      <geometry>
       <mesh filename="package://rob_pkg/meshes/roller.stl" scale="${roller_scale} ${roller_scale} ${roller_scale}"/>
      </geometry>
     </visual>
      <inertial>
      <mass value="${roller_mass}"/>
      <inertia ixx="${2.53776e-08}" ixy = "0" ixz = "0" iyy="${2.53776e-08}" iyz = "0" izz="${1.47666e-08}"/> 
    </inertial>
    </link>

    <xacro:surface_gen main_link_name="link_${wheel_name}_roller_3"/>

  <joint name="joint_${wheel_name}_3" type="continuous">
  <origin rpy="${1.5708} ${0} 0" xyz="${-0.0055*roller_scale} ${0*roller_scale} ${0.01355*roller_scale}"/>
    <child link="link_${wheel_name}_roller_3"/>
    <parent link="link_${wheel_name}_rim"/>
    <axis rpy="0 0 0" xyz="0 0 1"/>
    
  </joint>

     <link name="link_${wheel_name}_roller_4">
      <origin rpy="${2.35619} ${0} 0" xyz="${0.0055*roller_scale} ${-0.009581*roller_scale} ${0.009581*roller_scale}"/>
       <collision name="link_${wheel_name}_4_roller_collision">
        <geometry>
         <mesh filename="package://rob_pkg/meshes/roller.stl" scale="${roller_scale} ${roller_scale} ${roller_scale}"/>
        </geometry>
      </collision>
     <visual name="link_${wheel_name}_4_roller_visual">
      <geometry>
       <mesh filename="package://rob_pkg/meshes/roller.stl" scale="${roller_scale} ${roller_scale} ${roller_scale}"/>
      </geometry>
     </visual>
      <inertial>
      <mass value="${roller_mass}"/>
      <inertia ixx="${2.53776e-08}" ixy = "0" ixz = "0" iyy="${2.53776e-08}" iyz = "0" izz="${1.47666e-08}"/> 
    </inertial>
    </link>

    <xacro:surface_gen main_link_name="link_${wheel_name}_roller_4"/>

  <joint name="joint_${wheel_name}_4" type="continuous">
  <origin rpy="${2.35619} ${0} 0" xyz="${0.0055*roller_scale} ${-0.009581*roller_scale} ${0.009581*roller_scale}"/>
    <child link="link_${wheel_name}_roller_4"/>
    <parent link="link_${wheel_name}_rim"/>
    <axis rpy="0 0 0" xyz="0 0 1"/>
    
  </joint>

       <link name="link_${wheel_name}_roller_5">
      <origin rpy="${-3.14159} ${0} 0" xyz="${-0.0055*roller_scale} ${-0.01355*roller_scale} ${0*roller_scale}"/>
       <collision name="link_${wheel_name}_5_roller_collision">
        <geometry>
         <mesh filename="package://rob_pkg/meshes/roller.stl" scale="${roller_scale} ${roller_scale} ${roller_scale}"/>
        </geometry>
      </collision>
     <visual name="link_${wheel_name}_5_roller_visual">
      <geometry>
       <mesh filename="package://rob_pkg/meshes/roller.stl" scale="${roller_scale} ${roller_scale} ${roller_scale}"/>
      </geometry>
     </visual>
      <inertial>
      <mass value="${roller_mass}"/>
      <inertia ixx="${2.53776e-08}" ixy = "0" ixz = "0" iyy="${2.53776e-08}" iyz = "0" izz="${1.47666e-08}"/> 
    </inertial>
    </link>

<xacro:surface_gen main_link_name="link_${wheel_name}_roller_5"/>

  <joint name="joint_${wheel_name}_5" type="continuous">
  <origin rpy="${-3.14159} ${0} 0" xyz="${-0.0055*roller_scale} ${-0.01355*roller_scale} ${0*roller_scale}"/>
    <child link="link_${wheel_name}_roller_5"/>
    <parent link="link_${wheel_name}_rim"/>
    <axis rpy="0 0 0" xyz="0 0 1"/>
    
  </joint>

       <link name="link_${wheel_name}_roller_6">
      <origin rpy="${-2.35619} ${0} 0" xyz="${0.0055*roller_scale} ${-0.009581*roller_scale} ${-0.009581*roller_scale}"/>
       <collision name="link_${wheel_name}_6_roller_collision">
        <geometry>
         <mesh filename="package://rob_pkg/meshes/roller.stl" scale="${roller_scale} ${roller_scale} ${roller_scale}"/>
        </geometry>
      </collision>
     <visual name="link_${wheel_name}_6_roller_visual">
      <geometry>
       <mesh filename="package://rob_pkg/meshes/roller.stl" scale="${roller_scale} ${roller_scale} ${roller_scale}"/>
      </geometry>
     </visual>
      <inertial>
      <mass value="${roller_mass}"/>
      <inertia ixx="${2.53776e-08}" ixy = "0" ixz = "0" iyy="${2.53776e-08}" iyz = "0" izz="${1.47666e-08}"/> 
    </inertial>
    </link>

    <xacro:surface_gen main_link_name="link_${wheel_name}_roller_6"/>

  <joint name="joint_${wheel_name}_6" type="continuous">
  <origin rpy="${-2.35619} ${0} 0" xyz="${0.0055*roller_scale} ${-0.009581*roller_scale} ${-0.009581*roller_scale}"/>
    <child link="link_${wheel_name}_roller_6"/>
    <parent link="link_${wheel_name}_rim"/>
    <axis rpy="0 0 0" xyz="0 0 1"/>
    
  </joint>

         <link name="link_${wheel_name}_roller_7">
      <origin rpy="${-1.5708} ${0} 0" xyz="${-0.0055*roller_scale} ${0*roller_scale} ${-0.01355*roller_scale}"/>
       <collision name="link_${wheel_name}_7_roller_collision">
        <geometry>
         <mesh filename="package://rob_pkg/meshes/roller.stl" scale="${roller_scale} ${roller_scale} ${roller_scale}"/>
        </geometry>
      </collision>
     <visual name="link_${wheel_name}_7_roller_visual">
      <geometry>
       <mesh filename="package://rob_pkg/meshes/roller.stl" scale="${roller_scale} ${roller_scale} ${roller_scale}"/>
      </geometry>
     </visual>
      <inertial>
      <mass value="${roller_mass}"/>
      <inertia ixx="${2.53776e-08}" ixy = "0" ixz = "0" iyy="${2.53776e-08}" iyz = "0" izz="${1.47666e-08}"/> 
    </inertial>
    </link>


    <xacro:surface_gen main_link_name="link_${wheel_name}_roller_7"/>

  <joint name="joint_${wheel_name}_7" type="continuous">
  <origin rpy="${-1.5708} ${0} 0" xyz="${-0.0055*roller_scale} ${0*roller_scale} ${-0.01355*roller_scale}"/>
    <child link="link_${wheel_name}_roller_7"/>
    <parent link="link_${wheel_name}_rim"/>
    <axis rpy="0 0 0" xyz="0 0 1"/>
    
  </joint>


         <link name="link_${wheel_name}_roller_8">
      <origin rpy="${-0.875398} ${0} 0" xyz="${0.0055*roller_scale} ${0.009581*roller_scale} ${-0.009581*roller_scale}"/>
       <collision name="link_${wheel_name}_8_roller_collision">
        <geometry>
         <mesh filename="package://rob_pkg/meshes/roller.stl" scale="${roller_scale} ${roller_scale} ${roller_scale}"/>
        </geometry>
      </collision>
     <visual name="link_${wheel_name}_8_roller_visual">
      <geometry>
       <mesh filename="package://rob_pkg/meshes/roller.stl" scale="${roller_scale} ${roller_scale} ${roller_scale}"/>
      </geometry>
     </visual>
      <inertial>
      <mass value="${roller_mass}"/>
      <inertia ixx="${2.53776e-08}" ixy = "0" ixz = "0" iyy="${2.53776e-08}" iyz = "0" izz="${1.47666e-08}"/> 
    </inertial>
    </link>

    <xacro:surface_gen main_link_name="link_${wheel_name}_roller_8"/>

  <joint name="joint_${wheel_name}_8" type="continuous">
  <origin rpy="${-0.875398} ${0} 0" xyz="${0.0055*roller_scale} ${0.009581*roller_scale} ${-0.009581*roller_scale}"/>
    <child link="link_${wheel_name}_roller_8"/>
    <parent link="link_${wheel_name}_rim"/>
    <axis rpy="0 0 0" xyz="0 0 1"/>
    
  </joint>



  </xacro:macro>


</robot>