<?xml version="1.0" ?>
<robot name="complex_bot" xmlns:xacro="http://ros.org/wiki/xacro">
	<xacro:include filename="$(find rob_pkg)/urdf/complex_wheel.urdf.xacro"/>
 <xacro:property name="base_z" value="${rob_scale*0.52}"/>
    <xacro:property name="rob_scale" value="0.225"/>
    <xacro:property name="M_PI" value="3.1415926535897931" />
   <xacro:property name="right_wheel_x" value="${rob_scale*2.195}"/>
   <xacro:property name="right_wheel_y" value="${rob_scale*0}"/>
   <xacro:property name="right_wheel_z" value="${rob_scale*0.27}"/>
   <xacro:property name="right_wheel_length" value="${rob_scale*0.07}"/>
   <xacro:property name="right_wheel_radius" value="${rob_scale*0.27}"/>
   <xacro:property name="right_wheel_mass" value="${rob_scale*100}"/>
    

  <xacro:property name="left_wheel_x" value="${rob_scale*-1.10000}"/>
  <xacro:property name="left_wheel_y" value="${rob_scale*-1.9}"/>
  <xacro:property name="left_wheel_z" value="${rob_scale*0.27}"/>

  <xacro:property name="left_wheel_length" value="${rob_scale*0.07}"/>
  <xacro:property name="left_wheel_radius" value="${rob_scale*0.27}"/>
  <xacro:property name="left_wheel_mass" value="${rob_scale*100}"/>

  <xacro:property name="left2_wheel_x" value="${rob_scale*-1.10000}"/>
<xacro:property name="left2_wheel_y" value="${rob_scale*1.9}"/>
<xacro:property name="left2_wheel_z" value="${rob_scale*0.27}"/>

<xacro:property name="left2_wheel_length" value="${rob_scale*0.07}"/>
<xacro:property name="left2_wheel_radius" value="${rob_scale*0.27}"/>
<xacro:property name="left2_wheel_mass" value="${rob_scale*100}"/>

   <xacro:property name="rim_mass" value="${rob_scale*100}"/>
   <xacro:property name="roller_mass" value="${rob_scale*100}"/>
   <xacro:property name="wheel_scale" value="${3.0}"/>
   <xacro:property name="dummy_scale" value="${1000}"/>
   <xacro:property name="roller_scale" value="${3}"/>

	<link name="base_link">
    <inertial>
      <mass value="1000"/>
      <origin xyz="0 0 ${base_z}" rpy="0 0 3.14"/>
      <inertia ixx="0.738" ixy="0" ixz="0" iyy="0.738" iyz="-0.000000" izz="1.304"/>
    </inertial>
	<visual>
	<origin xyz="0 0 ${base_z}" rpy="0 0 3.14"/>
	<geometry>
        <mesh filename="package://rob_pkg/meshes/two_plate_s.dae" />
      </geometry>
    </visual>
    <collision >
	<origin xyz="0 0 ${base_z}" rpy="0 0 3.14"/>
      <geometry>
        <mesh filename="package://rob_pkg/meshes/two_plate_s.dae"   />
      </geometry>
    </collision>

  </link>


   <xacro:complex_wheel_gen wheel_name="my_wheel_1" this_wheel_x="${right_wheel_x}" this_wheel_y="${right_wheel_y}" this_wheel_z="${right_wheel_z}" this_wheel_pitch="0" this_wheel_yaw="0" this_wheel_roll="0"/>

   <joint name="joint_right_wheel" type="continuous">
	<origin rpy="0 0 0" xyz="${right_wheel_x} ${right_wheel_y} ${right_wheel_z}"/>
    <child link="link_my_wheel_1_rim"/>
    <parent link="base_link"/>
    <axis rpy="0 0 0" xyz="1 0 0"/>
  </joint>



   <xacro:complex_wheel_gen wheel_name="my_wheel_2" this_wheel_x="${left_wheel_x}" this_wheel_y="${left_wheel_y}" this_wheel_z="${left_wheel_z}" this_wheel_pitch="${0}" this_wheel_yaw="${0}" this_wheel_roll="1.0472" />

   <joint name="joint_left_wheel" type="continuous">
	<origin rpy="${0} 0 1.0472" xyz="${left_wheel_x} ${left_wheel_y} ${left_wheel_z}"/>
    <child link="link_my_wheel_2_rim"/>
    <parent link="base_link"/>
    <axis rpy="0 0 0" xyz="1 0 0"/>
  </joint>




   <xacro:complex_wheel_gen wheel_name="my_wheel_3" this_wheel_x="${left2_wheel_x}" this_wheel_y="${left2_wheel_y}" this_wheel_z="${left2_wheel_z}" this_wheel_pitch="0" this_wheel_yaw="0" this_wheel_roll="2.0944"/>

   <joint name="joint_left2_wheel" type="continuous">
	<origin rpy="0 0 2.0944" xyz="${left2_wheel_x} ${left2_wheel_y} ${left2_wheel_z}"/>
    <child link="link_my_wheel_3_rim"/>
    <parent link="base_link"/>
    <axis rpy="0 0 0" xyz="1 0 0"/>
  </joint>

</robot>