<?xml version="1.0"?>
<robot xmlns:xacro="http://www.ros.org/wiki/xacro" name="robot">

  <material name="black">
    <color rgba="0.0 0.0 0.0 1.0"/>
  </material>
  <material name="blue">
    <color rgba="0.203125 0.23828125 0.28515625 1.0"/>
  </material>
  <material name="green">
    <color rgba="0.0 0.8 0.0 1.0"/>
  </material>
  <material name="grey">
    <color rgba="0.2 0.2 0.2 1.0"/>
  </material>
  <material name="orange">
    <color rgba="1.0 0.423529411765 0.0392156862745 1.0"/>
  </material>
  <material name="brown">
    <color rgba="0.870588235294 0.811764705882 0.764705882353 1.0"/>
  </material>
  <material name="red">
    <color rgba="0.80078125 0.12890625 0.1328125 1.0"/>
  </material>
  <material name="white">
    <color rgba="1.0 1.0 1.0 1.0"/>
  </material>
  
    <gazebo reference="link_chassis">
    <material>Gazebo/Orange</material>
  </gazebo>
  <gazebo reference="link_left_wheel">
    <material>Gazebo/Orange</material>
  </gazebo>
  <gazebo reference="link_right_wheel">
    <material>Gazebo/Orange</material>
  </gazebo>
  <gazebo reference="link_left2_wheel">
    <material>Gazebo/Orange</material>
  </gazebo>
  <gazebo reference="camera_link">
    <material>Gazebo/Blue</material>
  </gazebo>
  
  <gazebo>
  <plugin name="gazebo_ros_control" filename="libgazebo_ros_control.so">
  <robotNamespace>/robot</robotNamespace> 
  </plugin>
</gazebo>
  
  <gazebo>
    <plugin filename="libgazebo_ros_diff_drive.so" name="differential_drive_controller">
      <alwaysOn>true</alwaysOn>
      <updateRate>20</updateRate>
      <leftJoint>joint_left_wheel</leftJoint>
      <rightJoint>joint_right_wheel</rightJoint>
      <wheelSeparation>0.4</wheelSeparation>
      <wheelDiameter>0.2</wheelDiameter>
      <torque>0.1</torque>
      <commandTopic>cmd_vel</commandTopic>
      <odometryTopic>odom</odometryTopic>
      <odometryFrame>odom</odometryFrame>
      <robotBaseFrame>link_chassis</robotBaseFrame>
    </plugin>
  </gazebo>
  
  <gazebo reference="sensor_laser">
    <sensor type="ray" name="head_hokuyo_sensor">
      <pose>0 0 0 0 0 0</pose>
      <visualize>false</visualize>
      <update_rate>20</update_rate>
      <ray>
        <scan>
          <horizontal>
            <samples>720</samples>
            <resolution>1</resolution>
            <min_angle>-1.570796</min_angle>
            <max_angle>1.570796</max_angle>
          </horizontal>
        </scan>
        <range>
          <min>0.10</min>
          <max>10.0</max>
          <resolution>0.01</resolution>
        </range>
        <noise>
          <type>gaussian</type>
          <mean>0.0</mean>
          <stddev>0.01</stddev>
        </noise>
      </ray>
      <plugin name="gazebo_ros_head_hokuyo_controller" filename="libgazebo_ros_laser.so">
        <topicName>/m2wr/laser/scan</topicName>
        <frameName>sensor_laser</frameName>
      </plugin>
    </sensor>
  </gazebo>
  
   <!--Interial macros-->
  <xacro:macro name="cylinder_inertia" params="m r h">
    <inertial>
      <mass value="${m}"/>
      <inertia ixx="${m*(3*r*r+h*h)/12}" ixy = "0" ixz = "0" iyy="${m*(3*r*r+h*h)/12}" iyz = "0" izz="${m*r*r/2}"/> 
    </inertial>
  </xacro:macro> 
  
  <xacro:macro name="box_inertia" params="m w h d">
    <inertial>
      <mass value="${m}"/>
      <inertia ixx="${m / 12.0 * (d*d + h*h)}" ixy="0.0" ixz="0.0" iyy="${m / 12.0 * (w*w + h*h)}" iyz="0.0" izz="${m / 12.0 * (w*w + d*d)}"/>
    </inertial>
  </xacro:macro>
 
 <xacro:property name="M_PI" value="3.1415926535897931" />
 
  <xacro:macro name="camera_link" params="parent">


    <link name="camera_link">

      <collision>
        <origin xyz="0 0 0.43" rpy="0 0 0" />
        <geometry>
          <box size=".1 .1 .1" />

        </geometry>
      </collision>

      <visual>
        <origin xyz="0 0 0.43" rpy="0 0 0" />
        <geometry>
          <box size=".1 .1 .1" />
        </geometry>
        <material name="grey">
            <color rgba="0.2 0.2 0.2 1.0"/>
        </material>
      </visual>


	<xacro:box_inertia m="0.001" w="0.1" h="0.1" d="0.1"/>

    </link>



    <joint name="camera_joint" type="fixed">
        <parent link="${parent}"/>
        <child link="camera_link"/>
        <origin rpy="0 0 0" xyz="2.195 0 0.5"/>
        <axis xyz="1 0 0" />
    </joint>



    <gazebo reference="camera_link">
      <sensor type="camera" name="camera_camera_sensor">
        <update_rate>30.0</update_rate>
        <camera>
          <pose>0.035 0 0.078 0 0 0</pose>
          <horizontal_fov>${85 * M_PI/180.0}</horizontal_fov>
          <image>
            <format>R8G8B8</format>
            <width>1020</width>
            <height>1020</height>
          </image>
          <clip>
            <near>0.01</near>
            <far>100</far>
          </clip>
        </camera>

        <plugin name="camera_camera_controller" filename="libgazebo_ros_camera.so">
          <alwaysOn>true</alwaysOn>
          <updateRate>0.0</updateRate>
          <cameraName>robot_sensor/camera</cameraName>
          <imageTopicName>image_raw</imageTopicName>
          <cameraInfoTopicName>camera_info</cameraInfoTopicName>
          <frameName>camera_link</frameName>
          <hackBaseline>0.07</hackBaseline>
          <distortionK1>0.0</distortionK1>
          <distortionK2>0.0</distortionK2>
          <distortionK3>0.0</distortionK3>
          <distortionT1>0.0</distortionT1>
          <distortionT2>0.0</distortionT2>
        </plugin>
      </sensor>
    </gazebo>
  </xacro:macro>
 

<link name="base_link">
    <inertial>
      <mass value="20"/>
      <origin xyz="0 0 0.52" rpy="0 0 3.14"/>
      <inertia ixx="1.392949" ixy="0" ixz="-0.000108" iyy="1.392846" iyz="-0.000000" izz="-1.000000"/>
    </inertial>
	<visual>
	<origin xyz="0 0 0.52" rpy="0 0 3.14"/>
	<geometry>
        <mesh filename="package://rob_pkg/meshes/two_plate.dae"/>
      </geometry>
      <material name="red"/>
    </visual>
    <collision >
	<origin xyz="0 0 0.52" rpy="0 0 3.14"/>
      <geometry>
        <mesh filename="package://rob_pkg/meshes/two_plate.dae"/>
      </geometry>
    </collision>

  </link>

  
  <xacro:camera_link parent="base_link" />
  
    <link name="link_right_wheel">
      <mass value="1"/>
      <origin rpy="0 1.570700 0" xyz="2.195 0 0.27"/>
    <collision name="link_right_wheel_collision">
	<geometry>
	 <cylinder length=".07" radius=".27" />
	</geometry>
    </collision>
    <visual name="link_right_wheel_visual">
	<geometry>
	 <cylinder length="0.07" radius="0.27" />
	</geometry>
    </visual>
    <xacro:cylinder_inertia m="1" r="0.27" h="0.07"/>
  </link>


  <joint name="joint_right_wheel" type="continuous">
	<origin rpy="0 1.570700 0" xyz="2.195 0 0.27"/>
    <child link="link_right_wheel"/>
    <parent link="base_link"/>
    <axis rpy="0 0 0" xyz="0 0 1"/>
  </joint>

<!-- Rear wheels transmission -->
<transmission name="transmission_right_wheel">
    <type>transmission_interface/SimpleTransmission</type>
    <joint name="joint_right_wheel">
        <hardwareInterface>hardware_interface/EffortJointInterface</hardwareInterface>
    </joint>
    <actuator name="motor_right_wheel">
        <hardwareInterface>hardware_interface/EffortJointInterface</hardwareInterface>
        <mechanicalReduction>1</mechanicalReduction>
    </actuator>
</transmission>





    <link name="link_left_wheel">
      <mass value="1"/>
      <origin rpy="0 1.570700 1.0472" xyz="-1.10000 -1.9 0.27"/>
    <collision name="link_left_wheel_collision">
	<geometry>
	 <cylinder length=".07" radius=".27" />
	</geometry>
    </collision>
    <visual name="link_left_wheel_visual">
	<geometry>
	 <cylinder length="0.07" radius="0.27" />
	</geometry>
    </visual>
    <xacro:cylinder_inertia m="1" r="0.27" h="0.07"/>
  </link>


  <joint name="joint_left_wheel" type="continuous">
  <origin rpy="0 1.570700 1.0472" xyz="-1.10000 -1.9 0.27"/>
    <child link="link_left_wheel"/>
    <parent link="base_link"/>
    <axis rpy="0 0 0" xyz="0 0 1"/>
  </joint>


<!-- Rear wheels transmission -->
<transmission name="transmission_left_wheel">
    <type>transmission_interface/SimpleTransmission</type>
    <joint name="joint_left_wheel">
        <hardwareInterface>hardware_interface/EffortJointInterface</hardwareInterface>
    </joint>
    <actuator name="motor_left_wheel">
        <hardwareInterface>hardware_interface/EffortJointInterface</hardwareInterface>
        <mechanicalReduction>1</mechanicalReduction>
    </actuator>
</transmission>


    <link name="link_left2_wheel">
      <mass value="1"/>
      <origin rpy="0 1.570700 2.0944" xyz="-1.10000 1.9 0.27"/>
    <collision name="link_left2_wheel_collision">
	<geometry>
	 <cylinder length=".07" radius=".27" />
	</geometry>
    </collision>
    <visual name="link_left2_wheel_visual">
	<geometry>
	 <cylinder length="0.07" radius="0.27" />
	</geometry>
    </visual>
    <xacro:cylinder_inertia m="1" r="0.27" h="0.07"/>
  </link>


  <joint name="joint_left2_wheel" type="continuous">
  <origin rpy="0 1.570700 2.0944" xyz="-1.10000 1.9 0.27"/>
    <child link="link_left2_wheel"/>
    <parent link="base_link"/>
    <axis rpy="0 0 0" xyz="0 0 1"/>
  </joint>

<!-- Rear wheels transmission -->
<transmission name="transmission_left2_wheel">
    <type>transmission_interface/SimpleTransmission</type>
    <joint name="joint_left2_wheel">
        <hardwareInterface>hardware_interface/EffortJointInterface</hardwareInterface>
    </joint>
    <actuator name="motor_left2_wheel">
        <hardwareInterface>hardware_interface/EffortJointInterface</hardwareInterface>
        <mechanicalReduction>1</mechanicalReduction>
    </actuator>
</transmission>


  
  
</robot>

